Workbook

Sheet Conso_elec
A1: Date | B1: Heure | C1: Consommation | D1: Eolien | E1: PV | F1: Hydro fil et lac | G1: Thermique fatal (biomasse, déchets, cogénération) | J1: Moyens de production thermiques | K1: Prix (€/MWh) | L1: Capacité (MW) | M1: Pmin (MW) | N1: Dmin (heures) | P1: Moyens de production hydraulique pilotables | Q1: Prix (€/MWh) | R1: Capacité (MW) | S1: Stock (MWh) | T1: Rendement
J2: Nucléaire | K2: 12 | L2: 6200 | M2: 1860 | N2: 24 | P2: Hydro lac | Q2: 0 | R2: 6000 | S2: 80053 | T2: -
A3: 43831 | B3: 0 | C3: 11075 | D3: 716 | E3: 0 | F3: 1873 | G3: 231 | J3: Charbon | K3: 36 | L3: =Parc_elec!C18 -> 1800 | M3: =0.35*L3 -> 630 | N3: 8 | P3: STEP | Q3: 0 | R3: 1200 | S3: =24*7*R3 -> 201600 | T3: 0.75
A4: 43831 | B4: 0.041666667 | C4: 10773 | D4: 569 | E4: 0 | F4: 1689 | G4: 228 | J4: Gaz semi-base | K4: 40 | L4: 2898 | M4: =0.35*L4 -> 1014.3 | N4: 4
A5: 43831 | B5: 0.083333333 | C5: 10431 | D5: 488 | E5: 0 | F5: 650 | G5: 223 | J5: Gaz pointe | K5: 70 | L5: 170 | M5: =0.4*L5 -> 68 | N5: 1
A6: 43831 | B6: 0.125 | C6: 9965 | D6: 371 | E6: 0 | F6: 650 | G6: 222 | J6: Fioul | K6: 100 | L6: 160 | M6: 50 | N6: 1
A7: 43831 | B7: 0.16666667 | C7: 9827 | D7: 385 | E7: 0 | F7: 872 | G7: 225
A8: 43831 | B8: 0.20833333 | C8: 10116 | D8: 344 | E8: 0 | F8: 745 | G8: 230
A9: 43831 | B9: 0.25 | C9: 10708 | D9: 355 | E9: 27 | F9: 960 | G9: 261
A10: 43831 | B10: 0.29166667 | C10: 11195 | D10: 467 | E10: 271 | F10: 650 | G10: 281
A11: 43831 | B11: 0.33333333 | C11: 11480 | D11: 486 | E11: 679 | F11: 1059 | G11: 283
A12: 43831 | B12: 0.375 | C12: 11712 | D12: 436 | E12: 1180 | F12: 650 | G12: 285
A13: 43831 | B13: 0.41666667 | C13: 11842 | D13: 487 | E13: 1542 | F13: 650 | G13: 289
A14: 43831 | B14: 0.45833333 | C14: 11977 | D14: 666 | E14: 1751 | F14: 719 | G14: 291
A15: 43831 | B15: 0.5 | C15: 12200 | D15: 653 | E15: 1890 | F15: 911 | G15: 289
A16: 43831 | B16: 0.54166667 | C16: 11772 | D16: 847 | E16: 2011 | F16: 650 | G16: 285
A17: 43831 | B17: 0.58333333 | C17: 11405 | D17: 932 | E17: 2123 | F17: 650 | G17: 274
A18: 43831 | B18: 0.625 | C18: 11147 | D18: 930 | E18: 2034 | F18: 650 | G18: 272
... A8762: 44196 | B8762: 0.95833333 | C8762: 11759 | D8762: 1181 | E8762: 0 | F8762: 1802 | G8762: 235

Sheet Parc_elec
A1: Centrale | B1: Type | C1: capacité installée (MW) | D1: nombre d'unités | E1: Pmax d'une unité (MW) | F1: Pmin (par unité) (MW) | G1: dmin marche/arrêt (hours) | H1: prix moyen sur le marché (€/MWh) | I1: année de lancement | J1: exploitant | K1: Divers - caractéristiques techniques | L1: Nord/Sud
A2: Gazby | B2: CCG gaz | D2: 1 | E2: 390 | F2: 135 | G2: 4 | H2: 40 | I2: 1994 | J2: Exploitant nucléaire | L2: S
A3: Omaïgaz1 | B3: CCG gaz | D3: 1 | E3: 430 | F3: 151 | G3: 4 | H3: 40 | I3: 2009 | J3: Producteur gaz | L3: S
A4: Omaïgaz2 | B4: CCG gaz | D4: 1 | E4: 430 | F4: 151 | G4: 4 | H4: 40 | I4: 2009 | J4: Producteur gaz | L4: S
A5: Igaznodon1 | B5: TAC gaz | D5: 1 | E5: 85 | F5: 34 | G5: 1 | H5: 70 | I5: 2004 | J5: Producteur gaz | L5: S
A6: Igaznodon2 | B6: TAC gaz | D6: 1 | E6: 85 | F6: 34 | G6: 1 | H6: 70 | I6: 2004 | J6: Producteur gaz | L6: S
A7: Cogénérations | B7: gaz cogénération | C7: 882 | D7: multiples | E7: 882 | F7: 0 | G7: 0 | H7: 70 | I7: années 2000 | J7: Producteur gaz | K7: production partielle conséquence de la production de chaleur | L7: S
A8: Pégaz | B8: CCG gaz | D8: 1 | E8: 394 | F8: 137 | G8: 4 | H8: 40 | I8: 2000 | J8: Exploitant nucléaire | L8: N
A9: Samagaz1 | B9: CCG gaz | D9: 1 | E9: 394 | F9: 137 | G9: 4 | H9: 40 | I9: 2000 | J9: Exploitant nucléaire | L9: N
A10: Samagaz2 | B10: CCG gaz | D10: 1 | E10: 430 | F10: 151 | G10: 4 | H10: 40 | I10: 2005 | J10: Exploitant nucléaire | L10: N
A11: Gastafiore | B11: CCG gaz | D11: 1 | E11: 430 | F11: 151 | G11: 4 | H11: 40 | I11: 2015 | J11: Producteur gaz | L11: N
A12: Iconuc1 | B12: Nucléaire (CP1) | C12: 6200 | D12: 1 | E12: 900 | F12: 300 | G12: 24 | H12: 12 | I12: 1977 | J12: Exploitant nucléaire
A13: Iconuc2 | B13: Nucléaire (CP1) | D13: 1 | E13: 900 | F13: 300 | G13: 24 | H13: 12 | I13: 1977 | J13: Exploitant nucléaire
A14: Tabarnuc1 | B14: Nucléaire (CP2) | D14: 1 | E14: 900 | F14: 300 | G14: 24 | H14: 12 | I14: 1981 | J14: Exploitant nucléaire
A15: Tabarnuc2 | B15: Nucléaire (CP2) | D15: 1 | E15: 900 | F15: 300 | G15: 24 | H15: 12 | I15: 1981 | J15: Exploitant nucléaire
A16: NucPlusUltra1 | B16: Nucléaire (P4) | D16: 1 | E16: 1300 | F16: 330 | G16: 24 | H16: 12 | I16: 1987 | J16: Exploitant nucléaire
A17: NucPlusUltra2 | B17: Nucléaire (P4) | D17: 1 | E17: 1300 | F17: 330 | G17: 24 | H17: 12 | I17: 1987 | J17: Exploitant nucléaire
A18: Coron1 | B18: charbon | C18: =E18*D18+E20*D20+E21*D21 -> 1800 | D18: 1 | E18: 600 | F18: 210 | G18: 8 | H18: 36 | I18: 1997 | J18: Exploitant nucléaire | K18: rendement 38%
A19: Coron2 | B19: charbon | D19: 1 | E19: 600 | F19: 210 | G19: 8 | H19: 36 | I19: 1997 | J19: Exploitant nucléaire | K19: rendement 38%
A20: Mockingjay | B20: charbon | D20: 1 | E20: 600 | F20: 210 | G20: 8 | H20: 36 | I20: 1990 | J20: Exploitant nucléaire | K20: rendement 38%
A21: Lantier | B21: charbon | D21: 1 | E21: 600 | F21: 210 | G21: 8 | H21: 36 | I21: 1984 | J21: Exploitant nucléaire | K21: rendement 38%
A22: Tacotac | B22: fioul | C22: 160 | D22: 1 | E22: 65 | F22: 20 | G22: 1 | H22: 100 | I22: 1990
A23: TicEtTac | B23: fioul | D23: 1 | E23: 95 | F23: 30 | G23: 1 | H23: 100 | I23: 2005 | J23: Exploitant nucléaire
A24: Polochon | B24: STEP | C24: 1200 | D24: 1 centrale à 8 pompes | E24: 1200 | F24: 0 | G24: 0 | H24: 0 | J24: Exploitant nucléaire | K24: rendement 75%, fonctionnement hébdomadaire, stock
B25: Parc éolien terrestre | C25: 5900 | I25: 2017 | J25: Exploitant nucléaire
A26: Zéphyr | B26: Parc éolien en mer | C26: 500 | J26: Selon les parcs (exploitant nuc + producteur gaz + autres)
B27: parc solaire | C27: 3000 | K27: divisé pour moitié entre parc au sol et toitures
B28: déchets | C28: 60 | D28: multiples | J28: Exploitant nucléaire | K28: production fatale
B29: petite biomasse | C29: 365 | D29: multiples | H29: - | K29: facteur de charge moyen = 60%
B30: hydraulique fil de l'eau | C30: 1000 | D30: multiples | H30: -
B31: hydraulique lac | C31: 6000 | H31: - | J31: Exploitant nucléaire | K31: stockage cumulé lacs : 1 TWh elec

Sheet Conso_gaz
A1: Date | B1: Consommation CH4 (GWh/j) | D1: Heure | E1: Date | F1: Consommation CH4 (GWh/h) | G1: Consommation H2 (GWh/h) | J1: Date | K1: Lev Low (%) | L1: Lev High (%) | N1: Lev Low (%) | O1: Lev High (%)
A2: 2018-01-01 | B2: 395.47839 | D2: =HOUR(TIME(ROW(A1)-1,0,0)) -> 0 | E2: {=INDEX($A$2:$A$1000,INT((ROW(A1)-1)/24)+1)} -> 2018-01-01 | F2: {=INDEX($B$2:$B$1000,INT((ROW(A1)-1)/24)+1)/24} -> 16.478266 | G2: =Données_gaz!F$24/(365*24) -> 0.00011415525 | J2: 2018-01-01 | K2: 0.32 | L2: 0.73 | N2: {=INDEX($K$2:$K$1000,INT((ROW(A1)-1)/24)+1)} -> 0.32 | O2: {=INDEX($L$2:$L$1000,INT((ROW(A1)-1)/24)+1)} -> 0.73
A3: 2018-01-02 | B3: 393.57631 | D3: =HOUR(TIME(ROW(A2)-1,0,0)) -> 1 | E3: {=INDEX($A$2:$A$1000,INT((ROW(A2)-1)/24)+1)} -> 2018-01-01 | F3: {=INDEX($B$2:$B$1000,INT((ROW(A2)-1)/24)+1)/24} -> 16.478266 | G3: =Données_gaz!F$24/(365*24) -> 0.00011415525 | J3: 2018-01-02 | K3: 0.315 | L3: 0.727 | N3: {=INDEX($K$2:$K$1000,INT((ROW(A2)-1)/24)+1)} -> 0.32 | O3: {=INDEX($L$2:$L$1000,INT((ROW(A2)-1)/24)+1)} -> 0.73
A4: 2018-01-03 | B4: 391.88938 | D4: =HOUR(TIME(ROW(A3)-1,0,0)) -> 2 | E4: {=INDEX($A$2:$A$1000,INT((ROW(A3)-1)/24)+1)} -> 2018-01-01 | F4: {=INDEX($B$2:$B$1000,INT((ROW(A3)-1)/24)+1)/24} -> 16.478266 | G4: =Données_gaz!F$24/(365*24) -> 0.00011415525 | J4: 2018-01-03 | K4: 0.309 | L4: 0.724 | N4: {=INDEX($K$2:$K$1000,INT((ROW(A3)-1)/24)+1)} -> 0.32 | O4: {=INDEX($L$2:$L$1000,INT((ROW(A3)-1)/24)+1)} -> 0.73
A5: 2018-01-04 | B5: 392.7644 | D5: =HOUR(TIME(ROW(A4)-1,0,0)) -> 3 | E5: {=INDEX($A$2:$A$1000,INT((ROW(A4)-1)/24)+1)} -> 2018-01-01 | F5: {=INDEX($B$2:$B$1000,INT((ROW(A4)-1)/24)+1)/24} -> 16.478266 | G5: =Données_gaz!F$24/(365*24) -> 0.00011415525 | J5: 2018-01-04 | K5: 0.304 | L5: 0.72 | N5: {=INDEX($K$2:$K$1000,INT((ROW(A4)-1)/24)+1)} -> 0.32 | O5: {=INDEX($L$2:$L$1000,INT((ROW(A4)-1)/24)+1)} -> 0.73
A6: 2018-01-05 | B6: 393.5663 | D6: =HOUR(TIME(ROW(A5)-1,0,0)) -> 4 | E6: {=INDEX($A$2:$A$1000,INT((ROW(A5)-1)/24)+1)} -> 2018-01-01 | F6: {=INDEX($B$2:$B$1000,INT((ROW(A5)-1)/24)+1)/24} -> 16.478266 | G6: =Données_gaz!F$24/(365*24) -> 0.00011415525 | J6: 2018-01-05 | K6: 0.298 | L6: 0.717 | N6: {=INDEX($K$2:$K$1000,INT((ROW(A5)-1)/24)+1)} -> 0.32 | O6: {=INDEX($L$2:$L$1000,INT((ROW(A5)-1)/24)+1)} -> 0.73
A7: 2018-01-06 | B7: 393.73939 | D7: =HOUR(TIME(ROW(A6)-1,0,0)) -> 5 | E7: {=INDEX($A$2:$A$1000,INT((ROW(A6)-1)/24)+1)} -> 2018-01-01 | F7: {=INDEX($B$2:$B$1000,INT((ROW(A6)-1)/24)+1)/24} -> 16.478266 | G7: =Données_gaz!F$24/(365*24) -> 0.00011415525 | J7: 2018-01-06 | K7: 0.293 | L7: 0.714 | N7: {=INDEX($K$2:$K$1000,INT((ROW(A6)-1)/24)+1)} -> 0.32 | O7: {=INDEX($L$2:$L$1000,INT((ROW(A6)-1)/24)+1)} -> 0.73
A8: 2018-01-07 | B8: 394.7192 | D8: =HOUR(TIME(ROW(A7)-1,0,0)) -> 6 | E8: {=INDEX($A$2:$A$1000,INT((ROW(A7)-1)/24)+1)} -> 2018-01-01 | F8: {=INDEX($B$2:$B$1000,INT((ROW(A7)-1)/24)+1)/24} -> 16.478266 | G8: =Données_gaz!F$24/(365*24) -> 0.00011415525 | J8: 2018-01-07 | K8: 0.287 | L8: 0.711 | N8: {=INDEX($K$2:$K$1000,INT((ROW(A7)-1)/24)+1)} -> 0.32 | O8: {=INDEX($L$2:$L$1000,INT((ROW(A7)-1)/24)+1)} -> 0.73
A9: 2018-01-08 | B9: 395.65882 | D9: =HOUR(TIME(ROW(A8)-1,0,0)) -> 7 | E9: {=INDEX($A$2:$A$1000,INT((ROW(A8)-1)/24)+1)} -> 2018-01-01 | F9: {=INDEX($B$2:$B$1000,INT((ROW(A8)-1)/24)+1)/24} -> 16.478266 | G9: =Données_gaz!F$24/(365*24) -> 0.00011415525 | J9: 2018-01-08 | K9: 0.282 | L9: 0.707 | N9: {=INDEX($K$2:$K$1000,INT((ROW(A8)-1)/24)+1)} -> 0.32 | O9: {=INDEX($L$2:$L$1000,INT((ROW(A8)-1)/24)+1)} -> 0.73
A10: 2018-01-09 | B10: 396.14813 | D10: =HOUR(TIME(ROW(A9)-1,0,0)) -> 8 | E10: {=INDEX($A$2:$A$1000,INT((ROW(A9)-1)/24)+1)} -> 2018-01-01 | F10: {=INDEX($B$2:$B$1000,INT((ROW(A9)-1)/24)+1)/24} -> 16.478266 | G10: =Données_gaz!F$24/(365*24) -> 0.00011415525 | J10: 2018-01-09 | K10: 0.276 | L10: 0.704 | N10: {=INDEX($K$2:$K$1000,INT((ROW(A9)-1)/24)+1)} -> 0.32 | O10: {=INDEX($L$2:$L$1000,INT((ROW(A9)-1)/24)+1)} -> 0.73
A11: 2018-01-10 | B11: 396.08339 | D11: =HOUR(TIME(ROW(A10)-1,0,0)) -> 9 | E11: {=INDEX($A$2:$A$1000,INT((ROW(A10)-1)/24)+1)} -> 2018-01-01 | F11: {=INDEX($B$2:$B$1000,INT((ROW(A10)-1)/24)+1)/24} -> 16.478266 | G11: =Données_gaz!F$24/(365*24) -> 0.00011415525 | J11: 2018-01-10 | K11: 0.271 | L11: 0.701 | N11: {=INDEX($K$2:$K$1000,INT((ROW(A10)-1)/24)+1)} -> 0.32 | O11: {=INDEX($L$2:$L$1000,INT((ROW(A10)-1)/24)+1)} -> 0.73
A12: 2018-01-11 | B12: 396.08339 | D12: =HOUR(TIME(ROW(A11)-1,0,0)) -> 10 | E12: {=INDEX($A$2:$A$1000,INT((ROW(A11)-1)/24)+1)} -> 2018-01-01 | F12: {=INDEX($B$2:$B$1000,INT((ROW(A11)-1)/24)+1)/24} -> 16.478266 | G12: =Données_gaz!F$24/(365*24) -> 0.00011415525 | J12: 2018-01-11 | K12: 0.265 | L12: 0.698 | N12: {=INDEX($K$2:$K$1000,INT((ROW(A11)-1)/24)+1)} -> 0.32 | O12: {=INDEX($L$2:$L$1000,INT((ROW(A11)-1)/24)+1)} -> 0.73
A13: 2018-01-12 | B13: 396.16052 | D13: =HOUR(TIME(ROW(A12)-1,0,0)) -> 11 | E13: {=INDEX($A$2:$A$1000,INT((ROW(A12)-1)/24)+1)} -> 2018-01-01 | F13: {=INDEX($B$2:$B$1000,INT((ROW(A12)-1)/24)+1)/24} -> 16.478266 | G13: =Données_gaz!F$24/(365*24) -> 0.00011415525 | J13: 2018-01-12 | K13: 0.26 | L13: 0.695 | N13: {=INDEX($K$2:$K$1000,INT((ROW(A12)-1)/24)+1)} -> 0.32 | O13: {=INDEX($L$2:$L$1000,INT((ROW(A12)-1)/24)+1)} -> 0.73
... A397: 2018-01-31 | B397: 367.4106 | D397: =HOUR(TIME(ROW(A396)-1,0,0)) -> 11 | E397: {=INDEX($A$2:$A$1000,INT((ROW(A396)-1)/24)+1)} -> 2018-01-17 | F397: {=INDEX($B$2:$B$1000,INT((ROW(A396)-1)/24)+1)/24} -> 16.539161 | G397: =Données_gaz!F$24/(365*24) -> 0.00011415525 | J397: 2018-01-31 | K397: 0.155 | L397: 0.633 | N397: {=INDEX($K$2:$K$1000,INT((ROW(A396)-1)/24)+1)} -> 0.232 | O397: {=INDEX($L$2:$L$1000,INT((ROW(A396)-1)/24)+1)} -> 0.678
D398: =HOUR(TIME(ROW(A397)-1,0,0)) -> 12 | E398: {=INDEX($A$2:$A$1000,INT((ROW(A397)-1)/24)+1)} -> 2018-01-17 | F398: {=INDEX($B$2:$B$1000,INT((ROW(A397)-1)/24)+1)/24} -> 16.539161 | G398: =Données_gaz!F$24/(365*24) -> 0.00011415525 | N398: {=INDEX($K$2:$K$1000,INT((ROW(A397)-1)/24)+1)} -> 0.232 | O398: {=INDEX($L$2:$L$1000,INT((ROW(A397)-1)/24)+1)} -> 0.678
D399: =HOUR(TIME(ROW(A398)-1,0,0)) -> 13 | E399: {=INDEX($A$2:$A$1000,INT((ROW(A398)-1)/24)+1)} -> 2018-01-17 | F399: {=INDEX($B$2:$B$1000,INT((ROW(A398)-1)/24)+1)/24} -> 16.539161 | G399: =Données_gaz!F$24/(365*24) -> 0.00011415525 | N399: {=INDEX($K$2:$K$1000,INT((ROW(A398)-1)/24)+1)} -> 0.232 | O399: {=INDEX($L$2:$L$1000,INT((ROW(A398)-1)/24)+1)} -> 0.678
D400: =HOUR(TIME(ROW(A399)-1,0,0)) -> 14 | E400: {=INDEX($A$2:$A$1000,INT((ROW(A399)-1)/24)+1)} -> 2018-01-17 | F400: {=INDEX($B$2:$B$1000,INT((ROW(A399)-1)/24)+1)/24} -> 16.539161 | G400: =Données_gaz!F$24/(365*24) -> 0.00011415525 | N400: {=INDEX($K$2:$K$1000,INT((ROW(A399)-1)/24)+1)} -> 0.232 | O400: {=INDEX($L$2:$L$1000,INT((ROW(A399)-1)/24)+1)} -> 0.678
D401: =HOUR(TIME(ROW(A400)-1,0,0)) -> 15 | E401: {=INDEX($A$2:$A$1000,INT((ROW(A400)-1)/24)+1)} -> 2018-01-17 | F401: {=INDEX($B$2:$B$1000,INT((ROW(A400)-1)/24)+1)/24} -> 16.539161 | G401: =Données_gaz!F$24/(365*24) -> 0.00011415525 | N401: {=INDEX($K$2:$K$1000,INT((ROW(A400)-1)/24)+1)} -> 0.232 | O401: {=INDEX($L$2:$L$1000,INT((ROW(A400)-1)/24)+1)} -> 0.678
D402: =HOUR(TIME(ROW(A401)-1,0,0)) -> 16 | E402: {=INDEX($A$2:$A$1000,INT((ROW(A401)-1)/24)+1)} -> 2018-01-17 | F402: {=INDEX($B$2:$B$1000,INT((ROW(A401)-1)/24)+1)/24} -> 16.539161 | G402: =Données_gaz!F$24/(365*24) -> 0.00011415525 | N402: {=INDEX($K$2:$K$1000,INT((ROW(A401)-1)/24)+1)} -> 0.232 | O402: {=INDEX($L$2:$L$1000,INT((ROW(A401)-1)/24)+1)} -> 0.678
D403: =HOUR(TIME(ROW(A402)-1,0,0)) -> 17 | E403: {=INDEX($A$2:$A$1000,INT((ROW(A402)-1)/24)+1)} -> 2018-01-17 | F403: {=INDEX($B$2:$B$1000,INT((ROW(A402)-1)/24)+1)/24} -> 16.539161 | G403: =Données_gaz!F$24/(365*24) -> 0.00011415525 | N403: {=INDEX($K$2:$K$1000,INT((ROW(A402)-1)/24)+1)} -> 0.232 | O403: {=INDEX($L$2:$L$1000,INT((ROW(A402)-1)/24)+1)} -> 0.678
D404: =HOUR(TIME(ROW(A403)-1,0,0)) -> 18 | E404: {=INDEX($A$2:$A$1000,INT((ROW(A403)-1)/24)+1)} -> 2018-01-17 | F404: {=INDEX($B$2:$B$1000,INT((ROW(A403)-1)/24)+1)/24} -> 16.539161 | G404: =Données_gaz!F$24/(365*24) -> 0.00011415525 | N404: {=INDEX($K$2:$K$1000,INT((ROW(A403)-1)/24)+1)} -> 0.232 | O404: {=INDEX($L$2:$L$1000,INT((ROW(A403)-1)/24)+1)} -> 0.678
D405: =HOUR(TIME(ROW(A404)-1,0,0)) -> 19 | E405: {=INDEX($A$2:$A$1000,INT((ROW(A404)-1)/24)+1)} -> 2018-01-17 | F405: {=INDEX($B$2:$B$1000,INT((ROW(A404)-1)/24)+1)/24} -> 16.539161 | G405: =Données_gaz!F$24/(365*24) -> 0.00011415525 | N405: {=INDEX($K$2:$K$1000,INT((ROW(A404)-1)/24)+1)} -> 0.232 | O405: {=INDEX($L$2:$L$1000,INT((ROW(A404)-1)/24)+1)} -> 0.678
D406: =HOUR(TIME(ROW(A405)-1,0,0)) -> 20 | E406: {=INDEX($A$2:$A$1000,INT((ROW(A405)-1)/24)+1)} -> 2018-01-17 | F406: {=INDEX($B$2:$B$1000,INT((ROW(A405)-1)/24)+1)/24} -> 16.539161 | G406: =Données_gaz!F$24/(365*24) -> 0.00011415525 | N406: {=INDEX($K$2:$K$1000,INT((ROW(A405)-1)/24)+1)} -> 0.232 | O406: {=INDEX($L$2:$L$1000,INT((ROW(A405)-1)/24)+1)} -> 0.678
D407: =HOUR(TIME(ROW(A406)-1,0,0)) -> 21 | E407: {=INDEX($A$2:$A$1000,INT((ROW(A406)-1)/24)+1)} -> 2018-01-17 | F407: {=INDEX($B$2:$B$1000,INT((ROW(A406)-1)/24)+1)/24} -> 16.539161 | G407: =Données_gaz!F$24/(365*24) -> 0.00011415525 | N407: {=INDEX($K$2:$K$1000,INT((ROW(A406)-1)/24)+1)} -> 0.232 | O407: {=INDEX($L$2:$L$1000,INT((ROW(A406)-1)/24)+1)} -> 0.678
D408: =HOUR(TIME(ROW(A407)-1,0,0)) -> 22 | E408: {=INDEX($A$2:$A$1000,INT((ROW(A407)-1)/24)+1)} -> 2018-01-17 | F408: {=INDEX($B$2:$B$1000,INT((ROW(A407)-1)/24)+1)/24} -> 16.539161 | G408: =Données_gaz!F$24/(365*24) -> 0.00011415525 | N408: {=INDEX($K$2:$K$1000,INT((ROW(A407)-1)/24)+1)} -> 0.232 | O408: {=INDEX($L$2:$L$1000,INT((ROW(A407)-1)/24)+1)} -> 0.678
D409: =HOUR(TIME(ROW(A408)-1,0,0)) -> 23 | E409: {=INDEX($A$2:$A$1000,INT((ROW(A408)-1)/24)+1)} -> 2018-01-17 | F409: {=INDEX($B$2:$B$1000,INT((ROW(A408)-1)/24)+1)/24} -> 16.539161 | G409: =Données_gaz!F$24/(365*24) -> 0.00011415525 | N409: {=INDEX($K$2:$K$1000,INT((ROW(A408)-1)/24)+1)} -> 0.232 | O409: {=INDEX($L$2:$L$1000,INT((ROW(A408)-1)/24)+1)} -> 0.678
... D8761: =HOUR(TIME(ROW(A8760)-1,0,0)) -> 23 | E8761: {=INDEX($A$2:$A$1000,INT((ROW(A8760)-1)/24)+1)} -> 2017-12-31 | F8761: {=INDEX($B$2:$B$1000,INT((ROW(A8760)-1)/24)+1)/24} -> 16.575114 | G8761: =Données_gaz!F$24/(365*24) -> 0.00011415525 | N8761: {=INDEX($K$2:$K$1000,INT((ROW(A8760)-1)/24)+1)} -> 0.326 | O8761: {=INDEX($L$2:$L$1000,INT((ROW(A8760)-1)/24)+1)} -> 0.734
C8762: Anneau de garde | D8762: =HOUR(TIME(ROW(A8761)-1,0,0)) -> 0 | E8762: {=INDEX($A$2:$A$1000,INT((ROW(A8761)-1)/24)+1)} -> 2018-01-01 | F8762: {=INDEX($B$2:$B$1000,INT((ROW(A8761)-1)/24)+1)/24} -> 16.478266 | G8762: =Données_gaz!F$24/(365*24) -> 0.00011415525 | N8762: {=INDEX($K$2:$K$1000,INT((ROW(A8761)-1)/24)+1)} -> 0.32 | O8762: {=INDEX($L$2:$L$1000,INT((ROW(A8761)-1)/24)+1)} -> 0.73
D8763: =HOUR(TIME(ROW(A8762)-1,0,0)) -> 1 | E8763: {=INDEX($A$2:$A$1000,INT((ROW(A8762)-1)/24)+1)} -> 2018-01-01 | F8763: {=INDEX($B$2:$B$1000,INT((ROW(A8762)-1)/24)+1)/24} -> 16.478266 | G8763: =Données_gaz!F$24/(365*24) -> 0.00011415525 | N8763: {=INDEX($K$2:$K$1000,INT((ROW(A8762)-1)/24)+1)} -> 0.32 | O8763: {=INDEX($L$2:$L$1000,INT((ROW(A8762)-1)/24)+1)} -> 0.73
D8764: =HOUR(TIME(ROW(A8763)-1,0,0)) -> 2 | E8764: {=INDEX($A$2:$A$1000,INT((ROW(A8763)-1)/24)+1)} -> 2018-01-01 | F8764: {=INDEX($B$2:$B$1000,INT((ROW(A8763)-1)/24)+1)/24} -> 16.478266 | G8764: =Données_gaz!F$24/(365*24) -> 0.00011415525 | N8764: {=INDEX($K$2:$K$1000,INT((ROW(A8763)-1)/24)+1)} -> 0.32 | O8764: {=INDEX($L$2:$L$1000,INT((ROW(A8763)-1)/24)+1)} -> 0.73
D8765: =HOUR(TIME(ROW(A8764)-1,0,0)) -> 3 | E8765: {=INDEX($A$2:$A$1000,INT((ROW(A8764)-1)/24)+1)} -> 2018-01-01 | F8765: {=INDEX($B$2:$B$1000,INT((ROW(A8764)-1)/24)+1)/24} -> 16.478266 | G8765: =Données_gaz!F$24/(365*24) -> 0.00011415525 | N8765: {=INDEX($K$2:$K$1000,INT((ROW(A8764)-1)/24)+1)} -> 0.32 | O8765: {=INDEX($L$2:$L$1000,INT((ROW(A8764)-1)/24)+1)} -> 0.73
D8766: =HOUR(TIME(ROW(A8765)-1,0,0)) -> 4 | E8766: {=INDEX($A$2:$A$1000,INT((ROW(A8765)-1)/24)+1)} -> 2018-01-01 | F8766: {=INDEX($B$2:$B$1000,INT((ROW(A8765)-1)/24)+1)/24} -> 16.478266 | G8766: =Données_gaz!F$24/(365*24) -> 0.00011415525 | N8766: {=INDEX($K$2:$K$1000,INT((ROW(A8765)-1)/24)+1)} -> 0.32 | O8766: {=INDEX($L$2:$L$1000,INT((ROW(A8765)-1)/24)+1)} -> 0.73
D8767: =HOUR(TIME(ROW(A8766)-1,0,0)) -> 5 | E8767: {=INDEX($A$2:$A$1000,INT((ROW(A8766)-1)/24)+1)} -> 2018-01-01 | F8767: {=INDEX($B$2:$B$1000,INT((ROW(A8766)-1)/24)+1)/24} -> 16.478266 | G8767: =Données_gaz!F$24/(365*24) -> 0.00011415525 | N8767: {=INDEX($K$2:$K$1000,INT((ROW(A8766)-1)/24)+1)} -> 0.32 | O8767: {=INDEX($L$2:$L$1000,INT((ROW(A8766)-1)/24)+1)} -> 0.73
D8768: =HOUR(TIME(ROW(A8767)-1,0,0)) -> 6 | E8768: {=INDEX($A$2:$A$1000,INT((ROW(A8767)-1)/24)+1)} -> 2018-01-01 | F8768: {=INDEX($B$2:$B$1000,INT((ROW(A8767)-1)/24)+1)/24} -> 16.478266 | G8768: =Données_gaz!F$24/(365*24) -> 0.00011415525 | N8768: {=INDEX($K$2:$K$1000,INT((ROW(A8767)-1)/24)+1)} -> 0.32 | O8768: {=INDEX($L$2:$L$1000,INT((ROW(A8767)-1)/24)+1)} -> 0.73
D8769: =HOUR(TIME(ROW(A8768)-1,0,0)) -> 7 | E8769: {=INDEX($A$2:$A$1000,INT((ROW(A8768)-1)/24)+1)} -> 2018-01-01 | F8769: {=INDEX($B$2:$B$1000,INT((ROW(A8768)-1)/24)+1)/24} -> 16.478266 | G8769: =Données_gaz!F$24/(365*24) -> 0.00011415525 | N8769: {=INDEX($K$2:$K$1000,INT((ROW(A8768)-1)/24)+1)} -> 0.32 | O8769: {=INDEX($L$2:$L$1000,INT((ROW(A8768)-1)/24)+1)} -> 0.73
D8770: =HOUR(TIME(ROW(A8769)-1,0,0)) -> 8 | E8770: {=INDEX($A$2:$A$1000,INT((ROW(A8769)-1)/24)+1)} -> 2018-01-01 | F8770: {=INDEX($B$2:$B$1000,INT((ROW(A8769)-1)/24)+1)/24} -> 16.478266 | G8770: =Données_gaz!F$24/(365*24) -> 0.00011415525 | N8770: {=INDEX($K$2:$K$1000,INT((ROW(A8769)-1)/24)+1)} -> 0.32 | O8770: {=INDEX($L$2:$L$1000,INT((ROW(A8769)-1)/24)+1)} -> 0.73
D8771: =HOUR(TIME(ROW(A8770)-1,0,0)) -> 9 | E8771: {=INDEX($A$2:$A$1000,INT((ROW(A8770)-1)/24)+1)} -> 2018-01-01 | F8771: {=INDEX($B$2:$B$1000,INT((ROW(A8770)-1)/24)+1)/24} -> 16.478266 | G8771: =Données_gaz!F$24/(365*24) -> 0.00011415525 | N8771: {=INDEX($K$2:$K$1000,INT((ROW(A8770)-1)/24)+1)} -> 0.32 | O8771: {=INDEX($L$2:$L$1000,INT((ROW(A8770)-1)/24)+1)} -> 0.73
D8772: =HOUR(TIME(ROW(A8771)-1,0,0)) -> 10 | E8772: {=INDEX($A$2:$A$1000,INT((ROW(A8771)-1)/24)+1)} -> 2018-01-01 | F8772: {=INDEX($B$2:$B$1000,INT((ROW(A8771)-1)/24)+1)/24} -> 16.478266 | G8772: =Données_gaz!F$24/(365*24) -> 0.00011415525 | N8772: {=INDEX($K$2:$K$1000,INT((ROW(A8771)-1)/24)+1)} -> 0.32 | O8772: {=INDEX($L$2:$L$1000,INT((ROW(A8771)-1)/24)+1)} -> 0.73
D8773: =HOUR(TIME(ROW(A8772)-1,0,0)) -> 11 | E8773: {=INDEX($A$2:$A$1000,INT((ROW(A8772)-1)/24)+1)} -> 2018-01-01 | F8773: {=INDEX($B$2:$B$1000,INT((ROW(A8772)-1)/24)+1)/24} -> 16.478266 | G8773: =Données_gaz!F$24/(365*24) -> 0.00011415525 | N8773: {=INDEX($K$2:$K$1000,INT((ROW(A8772)-1)/24)+1)} -> 0.32 | O8773: {=INDEX($L$2:$L$1000,INT((ROW(A8772)-1)/24)+1)} -> 0.73
D8774: =HOUR(TIME(ROW(A8773)-1,0,0)) -> 12 | E8774: {=INDEX($A$2:$A$1000,INT((ROW(A8773)-1)/24)+1)} -> 2018-01-01 | F8774: {=INDEX($B$2:$B$1000,INT((ROW(A8773)-1)/24)+1)/24} -> 16.478266 | G8774: =Données_gaz!F$24/(365*24) -> 0.00011415525 | N8774: {=INDEX($K$2:$K$1000,INT((ROW(A8773)-1)/24)+1)} -> 0.32 | O8774: {=INDEX($L$2:$L$1000,INT((ROW(A8773)-1)/24)+1)} -> 0.73
...

Sheet Données_gaz
A1: Date | B1: Consommation CH4 (GWh/j) | E1: Consommation gaz N-S | K1: Stockage gaz | O1: Date | P1: Lev Low (%) | Q1: Lev Avg (%) | R1: Lev High (%)
A2: 2017-07-01 | B2: 147.57265 | E2: Nord | F2: 0.4 | G2: consommation totale | O2: 2017-07-01 | P2: 0.33 | Q2: 0.585 | R2: 0.84
A3: 2017-07-02 | B3: 144.79333 | E3: Conso max Nord | F3: 163 | G3: GWh/j | K3: Volume utile (TWh) | L3: Capacité d'injection dans le stockage (GWh/j) | M3: Capacité de soutirage du stockage (GWh/j) | O3: 2017-07-02 | P3: 0.336 | Q3: 0.59 | R3: 0.843
A4: 2017-07-03 | B4: 144.21399 | E4: Sud | F4: 0.6 | G4: consommation totale | K4: 20 | L4: 200 | M4: 300 | O4: 2017-07-03 | P4: 0.343 | Q4: 0.594 | R4: 0.846
A5: 2017-07-04 | B5: 143.53787 | E5: Conso max Sud | F5: 244 | G5: GWh/j | O5: 2017-07-04 | P5: 0.349 | Q5: 0.599 | R5: 0.849
A6: 2017-07-05 | B6: 143.17218 | K6: Contraintes | O6: 2017-07-05 | P6: 0.356 | Q6: 0.604 | R6: 0.852
A7: 2017-07-06 | B7: 142.83394 | K7: Le stockage gaz doit être rempli à 88% le 1er octobre | O7: 2017-07-06 | P7: 0.362 | Q7: 0.608 | R7: 0.855
A8: 2017-07-07 | B8: 142.58891 | E8: Connexion N-S gaz | K8: Le stockage gaz doit se vider en hiver (octobre-avril) et se remplir en été (avril-octobre) suivant les courbes de niveaux suivantes | O8: 2017-07-07 | P8: 0.369 | Q8: 0.613 | R8: 0.857
A9: 2017-07-08 | B9: 142.29027 | E9: Capacité N-S et S-N | F9: 100 | G9: GWh/j | K9: Le niveau de remplissage du stockage gaz doit respecter (dans la mesure du possible) les contraintes de niveaux min et max données | O9: 2017-07-08 | P9: 0.375 | Q9: 0.618 | R9: 0.86
A10: 2017-07-09 | B10: 142.21403 | K10: NB : le niveau de remplissage moyen est donné à titre indicatif | O10: 2017-07-09 | P10: 0.382 | Q10: 0.622 | R10: 0.863
A11: 2017-07-10 | B11: 142.26305 | O11: 2017-07-10 | P11: 0.388 | Q11: 0.627 | R11: 0.866
A12: 2017-07-11 | B12: 142.34114 | E12: Production gaz | O12: 2017-07-11 | P12: 0.395 | Q12: 0.632 | R12: 0.869
A13: 2017-07-12 | B13: 142.80034 | E13: Zone | F13: type | H13: Pmax (GWh/j) | I13: Pmin (GWh/j) | J13: durée minimum marche et arrêt (h) | K13: Coût (€/MWh) | O13: 2017-07-12 | P13: 0.401 | Q13: 0.636 | R13: 0.872
A14: 2017-07-13 | B14: 143.08964 | E14: Sud | F14: Méthanisation | H14: 100 | I14: 96 | J14: 168 | K14: 24 | O14: 2017-07-13 | P14: 0.407 | Q14: 0.641 | R14: 0.875
A15: 2017-07-14 | B15: 143.54061 | E15: Sud | F15: Imports GNL* | H15: 300 | I15: 0 | J15: 1 | K15: 150 | O15: 2017-07-14 | P15: 0.414 | Q15: 0.646 | R15: 0.878
A16: 2017-07-15 | B16: 143.64132 | E16: Nord | F16: Méthanisation | H16: 50 | I16: 48 | J16: 168 | K16: 24 | O16: 2017-07-15 | P16: 0.42 | Q16: 0.65 | R16: 0.881
A17: 2017-07-16 | B17: 143.59431 | E17: Nord | F17: Pyrogazéification | H17: 50 | I17: 41 | J17: 168 | K17: 25 | O17: 2017-07-16 | P17: 0.427 | Q17: 0.655 | R17: 0.884
A18: 2017-07-17 | B18: 143.71141 | O18: 2017-07-17 | P18: 0.433 | Q18: 0.66 | R18: 0.886
A19: 2017-07-18 | B19: 144.36862 | F19: *GNL = Gaz Naturel Liquéfié, imports par bateau | O19: 2017-07-18 | P19: 0.44 | Q19: 0.665 | R19: 0.889
A20: 2017-07-19 | B20: 145.17778 | O20: 2017-07-19 | P20: 0.446 | Q20: 0.669 | R20: 0.892
A21: 2017-07-20 | B21: 145.91301 | O21: 2017-07-20 | P21: 0.453 | Q21: 0.674 | R21: 0.895
A22: 2017-07-21 | B22: 146.64216 | O22: 2017-07-21 | P22: 0.459 | Q22: 0.679 | R22: 0.898
A23: 2017-07-22 | B23: 147.67269 | E23: Consommation hydrogène | O23: 2017-07-22 | P23: 0.465 | Q23: 0.683 | R23: 0.901
A24: 2017-07-23 | B24: 148.56322 | E24: Nord | F24: 1 | G24: TWh/an | H24: (consommation constante, i.e., 1/365 TWh d'hydrogène consommé chaque jour) | O24: 2017-07-23 | P24: 0.472 | Q24: 0.688 | R24: 0.904
A25: 2017-07-24 | B25: 149.37409 | E25: Conso max Nord | F25: =1*1000/365 -> 2.739726 | G25: GWh/j | O25: 2017-07-24 | P25: 0.478 | Q25: 0.693 | R25: 0.907
A26: 2017-07-25 | B26: 150.52335 | E26: Sud | F26: 0 | G26: TWh/an | O26: 2017-07-25 | P26: 0.485 | Q26: 0.697 | R26: 0.91
A27: 2017-07-26 | B27: 152.10906 | E27: Conso max Sud | F27: 0 | G27: GWh/j | O27: 2017-07-26 | P27: 0.491 | Q27: 0.702 | R27: 0.913
A28: 2017-07-27 | B28: 153.39997 | O28: 2017-07-27 | P28: 0.498 | Q28: 0.707 | R28: 0.915
A29: 2017-07-28 | B29: 154.60879 | O29: 2017-07-28 | P29: 0.504 | Q29: 0.711 | R29: 0.918
A30: 2017-07-29 | B30: 155.87464 | E30: Connexion N-S hydrogène | O30: 2017-07-29 | P30: 0.511 | Q30: 0.716 | R30: 0.921
A31: 2017-07-30 | B31: 156.81099 | E31: Capacité N-S et S-N | F31: 2.5 | G31: GWh/j | O31: 2017-07-30 | P31: 0.517 | Q31: 0.721 | R31: 0.924
A32: 2017-07-31 | B32: 157.55482 | O32: 2017-07-31 | P32: 0.524 | Q32: 0.725 | R32: 0.927
A33: 2017-08-01 | B33: 158.57008 | O33: 2017-08-01 | P33: 0.53 | Q33: 0.73 | R33: 0.93
A34: 2017-08-02 | B34: 161.74838 | E34: Production hydrogène | O34: 2017-08-02 | P34: 0.535 | Q34: 0.734 | R34: 0.932
A35: 2017-08-03 | B35: 163.14727 | E35: Zone | F35: type | H35: Pmax (GWh/j) | I35: Pmin (GWh/j) | J35: durée minimum marche et arrêt (h) | K35: Coût (€/MWh) | O35: 2017-08-03 | P35: 0.541 | Q35: 0.737 | R35: 0.933
A36: 2017-08-04 | B36: 164.30447 | E36: Sud | F36: Electrolyse | H36: 2.5 | I36: 0 | J36: 1 | K36: 10 | O36: 2017-08-04 | P36: 0.546 | Q36: 0.741 | R36: 0.935
A37: 2017-08-05 | B37: 165.03073 | E37: Nord | F37: Vaporeformage | H37: 1 | I37: 0.3 | J37: 168 | K37: 50 | O37: 2017-08-05 | P37: 0.552 | Q37: 0.744 | R37: 0.936
A38: 2017-08-06 | B38: 165.75735 | O38: 2017-08-06 | P38: 0.557 | Q38: 0.748 | R38: 0.938
A39: 2017-08-07 | B39: 166.47478 | O39: 2017-08-07 | P39: 0.563 | Q39: 0.751 | R39: 0.94
A40: 2017-08-08 | B40: 168.1873 | O40: 2017-08-08 | P40: 0.568 | Q40: 0.755 | R40: 0.941
...

Sheet Rendements
A1: Rendement centrales électriques au gaz
A2: CCG | B2: 0.6 | C2: 1 MWh de gaz sert à produire 0,6 MWh d'électricité
A3: TAC | B3: 0.4 | C3: 1 MWh de gaz sert à produire 0,4 MWh d'électricité
A4: Cogénération | B4: 0.5 | C4: 1 MWh de gaz sert à produire 0,5 MWh d'électricité
A6: Rendements
A7: Electrolyse | B7: 0.7 | C7: 1 MWh d'électricité sert à produire 0,7 MWh d'hydrogène
A8: Vaporeformage | B8: 0.7 | C8: 1 MWh de gaz (CH4) sert à produire 0,8 MWh d'hydrogène
